Workbook

Sheet Merchant Dashboard
B1: Business Details | G1: Merchant Details | I1: Business Status | K1: Date | O1: Additional Comments
A2: Executive | B2: Merchant ID | C2: Business Name | D2: Seller Name | E2: Business Category | F2: Risk Level | G2: Contact No | H2: Email ID | I2: Stage | J2: Registration Status | K2: Submission Date | L2: Approval Date | M2: Onboarding Days | N2: Delay Alert
A3: Karan | B3: M0001 | C3: Smart Hub | D3: Amit Gupta | E3: Footwear | F3: Low | G3: 9829666443 | H3: amitgupta@example.com | I3: Document Review | J3: Pending | K3: 46034 | N3: AT RISK
A4: Neha | B4: M0002 | C4: Trend Kart | D4: Arjun Reddy | E4: Lingerie and Sleepwear | F4: High | G4: 9237732234 | H4: arjunreddy@example.com | I4: Compliance Check | J4: Approved | K4: 46049 | L4: 46056 | M4: 7
A5: Rahul | B5: M0003 | C5: Dream Store | D5: Rahul Nair | E5: Accessories | F5: Medium | G5: 9641716187 | H5: rahulnair@example.com | I5: Compliance Check | J5: Rejected | K5: 46065 | N5: AT RISK
A6: Rahul | B6: M0004 | C6: Prime Collection | D6: Priya Gupta | E6: Home and Living | F6: High | G6: 9599216711 | H6: priyagupta@example.com | I6: Final Approval | J6: Approved | K6: 46080 | L6: 46090 | M6: 10
A7: Rahul | B7: M0005 | C7: Prime World | D7: Riya Sharma | E7: Gadgets | F7: Low | G7: 9572300775 | H7: riyasharma@example.com | I7: Compliance Check | J7: Pending | K7: 46052 | N7: AT RISK
A8: Sneha | B8: M0006 | C8: Glow Bazaar | D8: Rahul Reddy | E8: Lingerie and Sleepwear | F8: Medium | G8: 9166079756 | H8: rahulreddy@example.com | I8: Final Approval | J8: Approved | K8: 46053 | L8: 46060 | M8: 7
A9: Neha | B9: M0007 | C9: Smart Collection | D9: Anita Das | E9: Beauty and Personal Care | F9: High | G9: 9286350678 | H9: anitadas@example.com | I9: Document Review | J9: Rejected | K9: 46068
A10: Rahul | B10: M0008 | C10: Prime World | D10: Vikas Reddy | E10: Accessories | F10: Medium | G10: 9496412732 | H10: vikasreddy@example.com | I10: Document Review | J10: Approved | K10: 46026 | L10: 46033 | M10: 7
A11: Rahul | B11: M0009 | C11: Smart Mart | D11: Rahul Patel | E11: Jewellery | F11: Medium | G11: 9624751727 | H11: rahulpatel@example.com | I11: Compliance Check | J11: Rejected | K11: 46065 | N11: AT RISK
A12: Rahul | B12: M0010 | C12: Dream Zone | D12: Anita Gupta | E12: Home and Living | F12: High | G12: 9174835913 | H12: anitagupta@example.com | I12: Compliance Check | J12: Approved | K12: 46073 | L12: 46080 | M12: 7
A13: Karan | B13: M0011 | C13: Style Zone | D13: Karan Nair | E13: Lingerie and Sleepwear | F13: Low | G13: 9804667173 | H13: karannair@example.com | I13: Compliance Check | J13: Pending | K13: 46060 | N13: AT RISK
A14: Sneha | B14: M0012 | C14: Active Bazaar | D14: Anita Reddy | E14: Bags and Luggage | F14: High | G14: 9705536955 | H14: anitareddy@example.com | I14: Compliance Check | J14: Pending | K14: 46065 | N14: AT RISK
A15: Sneha | B15: M0013 | C15: Trend Zone | D15: Arjun Nair | E15: Bags and Luggage | F15: Medium | G15: 9874713062 | H15: arjunnair@example.com | I15: Compliance Check | J15: Rejected | K15: 46056 | N15: AT RISK
A16: Neha | B16: M0014 | C16: Nova World | D16: Priya Mehta | E16: Footwear | F16: High | G16: 9293645211 | H16: priyamehta@example.com | I16: Final Approval | J16: Approved | K16: 46037 | L16: 46039 | M16: 2
A17: Karan | B17: M0015 | C17: Style Store | D17: Riya Das | E17: Gadgets | F17: Medium | G17: 9692232530 | H17: riyadas@example.com | I17: Final Approval | J17: Approved | K17: 46045 | L17: 46052 | M17: 7
A18: Arti | B18: M0016 | C18: Glow Hub | D18: Karan Nair | E18: Sports and Activewear | F18: Low | G18: 9409385375 | H18: karannair@example.com | I18: Final Approval | J18: Rejected | K18: 46080
A19: Neha | B19: M0017 | C19: Urban Zone | D19: Riya Verma | E19: Sports and Activewear | F19: High | G19: 9731255780 | H19: riyaverma@example.com | I19: Final Approval | J19: Pending | K19: 46029 | N19: OVERDUE
A20: Sneha | B20: M0018 | C20: Style Kart | D20: Neha Iyer | E20: Home and Living | F20: High | G20: 9125790943 | H20: nehaiyer@example.com | I20: Document Review | J20: Approved | K20: 46059 | L20: 46069 | M20: 10
A21: Arti | B21: M0019 | C21: Nova Store | D21: Priya Mehta | E21: Sports and Activewear | F21: Low | G21: 9252085185 | H21: priyamehta@example.com | I21: Final Approval | J21: Pending | K21: 46046 | N21: OVERDUE
A22: Sneha | B22: M0020 | C22: Trend Hub | D22: Priya Singh | E22: Home and Living | F22: Medium | G22: 9491883073 | H22: priyasingh@example.com | I22: Compliance Check | J22: Rejected | K22: 46068
A23: Karan | B23: M0021 | C23: Dream Bazaar | D23: Riya Sharma | E23: Beauty and Personal Care | F23: Medium | G23: 9198389930 | H23: riyasharma@example.com | I23: Compliance Check | J23: Rejected | K23: 46038 | N23: OVERDUE
A24: Arti | B24: M0022 | C24: Urban Hub | D24: Riya Sharma | E24: Bags and Luggage | F24: Medium | G24: 9564213163 | H24: riyasharma@example.com | I24: Final Approval | J24: Approved | K24: 46078 | L24: 46088 | M24: 10
A25: Neha | B25: M0023 | C25: Prime Zone | D25: Vikas Verma | E25: Accessories | F25: Low | G25: 9528182317 | H25: vikasverma@example.com | I25: Final Approval | J25: Approved | K25: 46028 | L25: 46038 | M25: 10
A26: Rahul | B26: M0024 | C26: Active Store | D26: Amit Sharma | E26: Home and Living | F26: Low | G26: 9862029191 | H26: amitsharma@example.com | I26: Document Review | J26: Pending | K26: 46028 | N26: OVERDUE
A27: Neha | B27: M0025 | C27: Dream Bazaar | D27: Karan Mehta | E27: Bags and Luggage | F27: Low | G27: 9452230663 | H27: karanmehta@example.com | I27: Compliance Check | J27: Approved | K27: 46038 | L27: 46047 | M27: 9
A28: Rahul | B28: M0026 | C28: Active Zone | D28: Sneha Iyer | E28: Beauty and Personal Care | F28: Medium | G28: 9159473516 | H28: snehaiyer@example.com | I28: Final Approval | J28: Pending | K28: 46055 | N28: AT RISK
A29: Neha | B29: M0027 | C29: Dream Mart | D29: Rahul Verma | E29: Beauty and Personal Care | F29: Low | G29: 9243077903 | H29: rahulverma@example.com | I29: Compliance Check | J29: Rejected | K29: 46034 | N29: OVERDUE
A30: Neha | B30: M0028 | C30: Smart Store | D30: Amit Mehta | E30: Bags and Luggage | F30: Low | G30: 9987651484 | H30: amitmehta@example.com | I30: Compliance Check | J30: Rejected | K30: 46027 | N30: OVERDUE
A31: Karan | B31: M0029 | C31: Glow World | D31: Karan Nair | E31: Footwear | F31: High | G31: 9126586846 | H31: karannair@example.com | I31: Compliance Check | J31: Pending | K31: 46031 | N31: OVERDUE
A32: Neha | B32: M0030 | C32: Nova Bazaar | D32: Priya Verma | E32: Sports and Activewear | F32: High | G32: 9540490883 | H32: priyaverma@example.com | I32: Document Review | J32: Rejected | K32: 46039 | N32: OVERDUE
A33: Arti | B33: M0031 | C33: Urban Hub | D33: Vikas Reddy | E33: Lingerie and Sleepwear | F33: Low | G33: 9188132607 | H33: vikasreddy@example.com | I33: Final Approval | J33: Approved | K33: 46069 | L33: 46071 | M33: 2
A34: Sneha | B34: M0032 | C34: Trend Kart | D34: Sneha Sharma | E34: Apparel | F34: Medium | G34: 9450861206 | H34: snehasharma@example.com | I34: Compliance Check | J34: Approved | K34: 46076 | L34: 46078 | M34: 2
A35: Arti | B35: M0033 | C35: Nova Kart | D35: Anita Patel | E35: Footwear | F35: Medium | G35: 9752617811 | H35: anitapatel@example.com | I35: Document Review | J35: Pending | K35: 46030 | N35: OVERDUE
A36: Karan | B36: M0034 | C36: Urban Kart | D36: Sneha Singh | E36: Footwear | F36: High | G36: 9285065237 | H36: snehasingh@example.com | I36: Compliance Check | J36: Pending | K36: 46059 | N36: AT RISK
A37: Sneha | B37: M0035 | C37: Style Mart | D37: Sneha Sharma | E37: Bags and Luggage | F37: Medium | G37: 9224045794 | H37: snehasharma@example.com | I37: Document Review | J37: Pending | K37: 46078
A38: Karan | B38: M0036 | C38: Dream Collection | D38: Vikas Singh | E38: Accessories | F38: Low | G38: 9758312904 | H38: vikassingh@example.com | I38: Final Approval | J38: Rejected | K38: 46068
A39: Neha | B39: M0037 | C39: Glow World | D39: Karan Iyer | E39: Apparel | F39: Medium | G39: 9185097287 | H39: karaniyer@example.com | I39: Compliance Check | J39: Approved | K39: 46079 | L39: 46081 | M39: 2
A40: Karan | B40: M0038 | C40: Active Kart | D40: Riya Verma | E40: Apparel | F40: Medium | G40: 9835837552 | H40: riyaverma@example.com | I40: Final Approval | J40: Rejected | K40: 46038 | N40: OVERDUE
...

Sheet 📊 KPI Metrics & Visual Dashboa
A1: 📊 KPI METRICS & EXECUTIVE PERFORMANCE | M1: EXECUTIVE PERFORMANCE SCORECARD | U1: Category | V1: Count
M2: Executive | N2: Total | O2: Approved | P2: Rejected | Q2: Pending | R2: Approval % | S2: Avg Days | U2: Sports and Activewear | V2: =COUNTIFS('Merchant Dashboard'!E3:E999,U2) -> 57
A3: Total Merchants | D3: Approved | G3: Rejected | J3: Pending | M3: Rahul | N3: =COUNTIF('Merchant Dashboard'!A3:A999,M3) -> 107 | O3: =COUNTIFS( 'Merchant Dashboard'!A3:A999,M3, 'Merchant Dashboard'!J3:J999,O2 ) -> 39 | P3: =COUNTIFS( 'Merchant Dashboard'!A3:A999,M3, 'Merchant Dashboard'!J3:J999,P2 ) -> 34 | Q3: =COUNTIFS( 'Merchant Dashboard'!A3:A999,M3, 'Merchant Dashboard'!J3:J999,Q2 ) -> 34 | R3: =O3/N3 -> 0.36448598 | S3: =AVERAGEIFS('Merchant Dashboard'!M3:M999, 'Merchant Dashboard'!A3:A999,M3) -> 6.7948718 | U3: Bags and Luggage | V3: =COUNTIFS('Merchant Dashboard'!E3:E999,U3) -> 56
A4: =COUNTA('Merchant Dashboard'!B3:B999) -> 500 | D4: =COUNTIF('Merchant Dashboard'!J3:J503,"Approved") -> 175 | G4: =COUNTIF('Merchant Dashboard'!J3:J999,"Rejected") -> 171 | J4: =COUNTIF('Merchant Dashboard'!J3:J999,"Pending") -> 154 | M4: Arti | N4: =COUNTIF('Merchant Dashboard'!A3:A999,M4) -> 106 | O4: =COUNTIFS( 'Merchant Dashboard'!A3:A999,M4, 'Merchant Dashboard'!J3:J999,O2 ) -> 32 | P4: =COUNTIFS( 'Merchant Dashboard'!A4:A999,M4, 'Merchant Dashboard'!J4:J999,P2 ) -> 46 | Q4: =COUNTIFS( 'Merchant Dashboard'!A4:A999,M4, 'Merchant Dashboard'!J4:J999,Q2 ) -> 28 | R4: =O4/N4 -> 0.30188679 | S4: =AVERAGEIFS('Merchant Dashboard'!M3:M999, 'Merchant Dashboard'!A3:A999,M4) -> 5.8125 | U4: Lingerie and Sleepwear | V4: =COUNTIFS('Merchant Dashboard'!E3:E999,U4) -> 54
M5: Karan | N5: =COUNTIF('Merchant Dashboard'!A4:A999,M5) -> 95 | O5: =COUNTIFS( 'Merchant Dashboard'!A4:A999,M5, 'Merchant Dashboard'!J4:J999,"Approved" ) -> 31 | P5: =COUNTIFS( 'Merchant Dashboard'!A5:A999,M5, 'Merchant Dashboard'!J5:J999,"Rejected" ) -> 30 | Q5: =COUNTIFS( 'Merchant Dashboard'!A5:A999,M5, 'Merchant Dashboard'!J5:J999,Q2 ) -> 34 | R5: =O5/N5 -> 0.32631579 | S5: =AVERAGEIFS('Merchant Dashboard'!M3:M999, 'Merchant Dashboard'!A3:A999,M5) -> 6.0645161 | U5: Jewellery | V5: =COUNTIFS('Merchant Dashboard'!E3:E999,U5) -> 53
A6: Approval Rate | D6: Avg Onboarding Days | G6: Overdue | J6: At-Risk | M6: Sneha | N6: =COUNTIF('Merchant Dashboard'!A5:A999,M6) -> 96 | O6: =COUNTIFS( 'Merchant Dashboard'!A5:A999,M6, 'Merchant Dashboard'!J5:J999,O2 ) -> 34 | P6: =COUNTIFS( 'Merchant Dashboard'!A6:A999,M6, 'Merchant Dashboard'!J6:J999,P2 ) -> 31 | Q6: =COUNTIFS( 'Merchant Dashboard'!A6:A999,M6, 'Merchant Dashboard'!J6:J999,"Pending" ) -> 31 | R6: =O6/N6 -> 0.35416667 | S6: =AVERAGEIFS('Merchant Dashboard'!M3:M999, 'Merchant Dashboard'!A3:A999,M6) -> 6.4411765 | U6: Beauty and Personal Care | V6: =COUNTIFS('Merchant Dashboard'!E3:E999,U6) -> 52
A7: =D4/A4 -> 0.35 | D7: =AVERAGE('Merchant Dashboard'!M3:M999) -> 6.2742857 | G7: =COUNTIF('Merchant Dashboard'!N3:N999,"OVERDUE") -> 161 | J7: =COUNTIF('Merchant Dashboard'!N3:N999,"AT RISK") -> 86 | M7: Neha | N7: =COUNTIF('Merchant Dashboard'!A6:A999,M7) -> 94 | O7: =COUNTIFS( 'Merchant Dashboard'!A6:A999,M7, 'Merchant Dashboard'!J6:J999,O2 ) -> 38 | P7: =COUNTIFS( 'Merchant Dashboard'!A7:A999,M7, 'Merchant Dashboard'!J7:J999,P2 ) -> 30 | Q7: =COUNTIFS( 'Merchant Dashboard'!A7:A999,M7, 'Merchant Dashboard'!J7:J999,Q2 ) -> 26 | R7: =O7/N7 -> 0.40425532 | S7: =AVERAGEIFS('Merchant Dashboard'!M3:M999, 'Merchant Dashboard'!A3:A999,M7) -> 6.1538462 | U7: Gadgets | V7: =COUNTIFS('Merchant Dashboard'!E3:E999,U7) -> 51
U8: Apparel | V8: =COUNTIFS('Merchant Dashboard'!E3:E999,U8) -> 48
A9: STAGE FUNNEL | M9: Month | N9: Submissions | O9: Approved | Q9: Risk | R9: Count | U9: Home and Living | V9: =COUNTIFS('Merchant Dashboard'!E3:E999,U9) -> 46
A10: Stage | B10: Count | C10: Approved | D10: Rejected | E10: Pending | M10: 2025-12 | N10: 20 | O10: 4 | Q10: Low | R10: =COUNTIFS('Merchant Dashboard'!F3:F999,Q10) -> 162
A11: Document Review | B11: =COUNTIF('Merchant Dashboard'!I3:I999,A11) -> 168 | C11: =COUNTIFS('Merchant Dashboard'!I3:I999,A11,'Merchant Dashboard'!J3:J999,C10) -> 59 | D11: =COUNTIFS('Merchant Dashboard'!I3:I999,A11,'Merchant Dashboard'!J3:J999,D10) -> 53 | E11: =COUNTIFS('Merchant Dashboard'!I3:I999,A11,'Merchant Dashboard'!J3:J999,E10) -> 56 | M11: 2026-01 | N11: 251 | O11: 87 | Q11: Medium | R11: =COUNTIFS('Merchant Dashboard'!F3:F999,Q11) -> 180
A12: Compliance Check | B12: =COUNTIF('Merchant Dashboard'!I3:I999,A12) -> 149 | C12: =COUNTIFS('Merchant Dashboard'!I3:I999,A12,'Merchant Dashboard'!J3:J999,C10) -> 46 | D12: =COUNTIFS('Merchant Dashboard'!I3:I999,A12,'Merchant Dashboard'!J3:J999,D10) -> 54 | E12: =COUNTIFS('Merchant Dashboard'!I3:I999,A12,'Merchant Dashboard'!J3:J999,E10) -> 49 | M12: 2026-02 | N12: 229 | O12: 84 | Q12: High | R12: =COUNTIFS('Merchant Dashboard'!F3:F999,Q12) -> 158
A13: Final Approval | B13: =COUNTIF('Merchant Dashboard'!I3:I999,A13) -> 183 | C13: =COUNTIFS('Merchant Dashboard'!I3:I999,A13,'Merchant Dashboard'!J3:J999,C10) -> 70 | D13: =COUNTIFS('Merchant Dashboard'!I3:I999,A13,'Merchant Dashboard'!J3:J999,D10) -> 64 | E13: =COUNTIFS('Merchant Dashboard'!I3:I999,A13,'Merchant Dashboard'!J3:J999,E10) -> 49
